Workbook

Sheet Overview
B1: Medical Store Inventory & Sales Analytics
B2: A beginner-friendly data analytics project built with Google Sheets-compatible formulas
B4: Objective
B5: Analyse medical-store sales and purchase transactions together with the medicine master list to find sales trends, top-performing medicines and categories, restocking needs, slow movers and expiry risks, then turn them into business recommendations.
B7: Workbook guide
B8: Sheet | C8: Purpose
B9: Dashboard | C9: KPI cards and 6 charts - the page to present
B10: Analysis | C10: KPIs and pivot-style summary tables (by category, month, type, medicine, restock, expiry)
B11: Insights | C11: Business insights and recommendations, each tied to a number
B12: Data_Cleaning | C12: All data-quality checks with PASS / REVIEW / FAIL results
B13: transactions | C13: Cleaned transaction data + calculated columns (sales amount, cost, profit, month ...)
B14: medicine_master | C14: Cleaned medicine list + calculated columns (margin, expiry status, units sold, restock priority ...)
B16: Business definitions
B17: Sales Amount | C17: Quantity x Selling_Rate, only for rows where Transaction_Type = Sale (Purchase rows = 0)
B18: Cost of Goods Sold / Gross Profit | C18: Quantity x Purchase_Rate for Sale rows / Sales Amount - Cost of Goods Sold
B19: Purchase Spend | C19: Quantity x Purchase_Rate, only for Purchase rows
B21: Assumptions (blue cells can be edited - the whole workbook recalculates)
B22: Analysis date | C22: 46300 | D22: Reference date for expiry calculations (the date this analysis was prepared)
B23: Critical expiry: within (days) | C23: 90 | D23: Days to expiry <= this value = "Critical"
B24: Expiring Soon: within (days) | C24: 180 | D24: Days to expiry <= this value (and above Critical) = "Expiring Soon"
B25: Watch: within (days) | C25: 365 | D25: Days to expiry <= this value (and above Expiring Soon) = "Watch"; above = "Safe"
B26: High restock priority: Sold/Purchased >= | C26: 1.75 | D26: Medicines that sold at least this many units per unit purchased = "High" restock priority (analyst-chosen threshold)
B27: Medium restock priority: Sold/Purchased >= | C27: 1.4 | D27: Between this value and the High threshold = "Medium"; below = "Low" (analyst-chosen threshold)
B29: Important data notes
B30: 1. No stock/inventory column exists in the data and no opening stock is given. Stock was therefore NOT invented; restock need is judged from the Sold-to-Purchased ratio instead.
B31: 2. Currency is not stated in the data. Amounts are shown in rupees (₹) as an assumption.
B32: 3. 609 of 2,600 transactions are dated after the analysis date (5 Oct 2026); the data covers all of 2026. They are kept, and flagged on the Data_Cleaning sheet.
B33: 4. Pivot-style tables in the Analysis sheet are built with SUMIFS/COUNTIF formulas so they update automatically; steps to create real Google Sheets Pivot Tables are in the project report.

Sheet Dashboard
B1: MEDICAL STORE ANALYTICS DASHBOARD
B2: ="Year 2026 | Analysis date: "&TEXT(Overview!C22,"dd mmm yyyy")&" | Amounts in ₹" -> Year 2026 | Analysis date: 05 Oct 2026 | Amounts in ₹
B3: Total Revenue | D3: Total Transactions | F3: Units Sold | H3: Medicines | J3: High-Priority Restock | L3: Expiring ≤ 1 Year
B4: =Analysis!$B$10 -> 1811440 | D4: =Analysis!$B$5 -> 2600 | F4: =Analysis!$B$8 -> 37285 | H4: =Analysis!$B$17 -> 25 | J4: =Analysis!$B$22 -> 9 | L4: =Analysis!$B$23 -> 11
B5: ="Gross profit "&TEXT(Analysis!$B$12,"₹#,##0") -> Gross profit ₹538,920 | D5: =TEXT(Analysis!$B$6,"#,##0")&" sales / "&TEXT(Analysis!$B$7,"#,##0")&" purchases" -> 1,594 sales / 1,006 purchases | F5: ="Purchased: "&TEXT(Analysis!$B$9,"#,##0") -> Purchased: 23,595 | H5: =TEXT(Analysis!$B$18,"0")&" categories" -> 10 categories | J5: ="Sold ÷ purchased ratio ≥ "&TEXT(Overview!C26,"0.00") -> Sold ÷ purchased ratio ≥ 1.75 | L5: ="Within "&Overview!C25&" days of analysis date" -> Within 365 days of analysis date
B58: Source: Analysis sheet. All figures update automatically if the data or the assumptions on the Overview sheet change.

Sheet Analysis
A1: Analysis - KPIs and pivot-style summary tables
A2: Every number below is a formula that reads the transactions and medicine_master sheets.
A3: 1. Key Performance Indicators (KPIs)
A4: KPI | B4: Value | C4: How it is calculated
A5: Total Transactions | B5: =COUNTA(transactions!$A$2:$A$2601) -> 2600 | C5: Count of Transaction_IDs
A6: Sale Transactions | B6: =COUNTIF(transactions!$D$2:$D$2601,"Sale") -> 1594 | C6: Rows where Transaction_Type = Sale
A7: Purchase Transactions | B7: =COUNTIF(transactions!$D$2:$D$2601,"Purchase") -> 1006 | C7: Rows where Transaction_Type = Purchase
A8: Total Units Sold | B8: =SUMIFS(transactions!$E$2:$E$2601,transactions!$D$2:$D$2601,"Sale") -> 37285 | C8: Sum of Quantity for Sale rows
A9: Total Units Purchased | B9: =SUMIFS(transactions!$E$2:$E$2601,transactions!$D$2:$D$2601,"Purchase") -> 23595 | C9: Sum of Quantity for Purchase rows
A10: Total Revenue | B10: =SUM(transactions!$N$2:$N$2601) -> 1811440 | C10: Sum of Sales_Amount
A11: Cost of Goods Sold | B11: =SUM(transactions!$O$2:$O$2601) -> 1272520 | C11: Sum of Cost_of_Goods_Sold
A12: Gross Profit | B12: =B10-B11 -> 538920 | C12: Revenue - Cost of Goods Sold
A13: Gross Profit Margin | B13: =IF(B10=0,0,B12/B10) -> 0.29750916 | C13: Gross Profit / Revenue
A14: Total Purchase Spend | B14: =SUM(transactions!$Q$2:$Q$2601) -> 757815 | C14: Sum of Purchase_Spend
A15: Average Units per Transaction | B15: =AVERAGE(transactions!$E$2:$E$2601) -> 23.415385 | C15: Average Quantity across all rows
A16: Average Revenue per Sale | B16: =IF(B6=0,0,B10/B6) -> 1136.4115 | C16: Revenue / Sale transactions
A17: Number of Medicines | B17: =COUNTA(medicine_master!$A$2:$A$26) -> 25 | C17: Rows in medicine_master
A18: Number of Categories | B18: =SUMPRODUCT(1/COUNTIF(medicine_master!$C$2:$C$26,medicine_master!$C$2:$C$26)) -> 10 | C18: Distinct category names
A19: Best-Selling Medicine (Units) | B19: =INDEX(medicine_master!$B$2:$B$26,MATCH(MAX(medicine_master!$O$2:$O$26),medicine_master!$O$2:$O$26,0)) -> Glimepiride 2mg | C19: Medicine with the most units sold
A20: Highest-Revenue Medicine | B20: =INDEX(medicine_master!$B$2:$B$26,MATCH(MAX(medicine_master!$R$2:$R$26),medicine_master!$R$2:$R$26,0)) -> Insulin Injection | C20: Medicine with the highest Sales_Revenue
A21: Best-Performing Category (Revenue) | B21: =INDEX($A$28:$A$37,MATCH(MAX($E$28:$E$37),$E$28:$E$37,0)) -> Diabetes | C21: Category with the highest revenue (table 2)
A22: High-Priority Restock Medicines | B22: =COUNTIF(medicine_master!$T$2:$T$26,"High") -> 9 | C22: Sold/Purchased ratio >= High threshold (Overview)
A23: Medicines Expired or Expiring Within 1 Year | B23: =COUNTIF(medicine_master!$L$2:$L$26,"<="&Overview!$C$25) -> 11 | C23: Days to expiry <= Watch threshold (Overview)
A26: 2. Sales by Category | C26: Pivot-style: Rows = Category, Values = Units, Revenue, Profit
A27: Category | B27: Medicines | C27: % of Medicines | D27: Units Sold | E27: Revenue | F27: % of Revenue | G27: Gross Profit | H27: Margin %
A28: Diabetes | B28: =COUNTIF(medicine_master!$C$2:$C$26,A28) -> 3 | C28: =B28/B$38 -> 0.12 | D28: =SUMIFS(transactions!$E$2:$E$2601,transactions!$H$2:$H$2601,A28,transactions!$D$2:$D$2601,"Sale") -> 5095 | E28: =SUMIFS(transactions!$N$2:$N$2601,transactions!$H$2:$H$2601,A28) -> 517360 | F28: =E28/E$38 -> 0.28560703 | G28: =SUMIFS(transactions!$P$2:$P$2601,transactions!$H$2:$H$2601,A28) -> 140420 | H28: =IF(E28=0,0,G28/E28) -> 0.27141642
A29: Cold & Cough | B29: =COUNTIF(medicine_master!$C$2:$C$26,A29) -> 2 | C29: =B29/B$38 -> 0.08 | D29: =SUMIFS(transactions!$E$2:$E$2601,transactions!$H$2:$H$2601,A29,transactions!$D$2:$D$2601,"Sale") -> 3055 | E29: =SUMIFS(transactions!$N$2:$N$2601,transactions!$H$2:$H$2601,A29) -> 232760 | F29: =E29/E$38 -> 0.12849446 | G29: =SUMIFS(transactions!$P$2:$P$2601,transactions!$H$2:$H$2601,A29) -> 64300 | H29: =IF(E29=0,0,G29/E29) -> 0.27625021
A30: Vitamin | B30: =COUNTIF(medicine_master!$C$2:$C$26,A30) -> 2 | C30: =B30/B$38 -> 0.08 | D30: =SUMIFS(transactions!$E$2:$E$2601,transactions!$H$2:$H$2601,A30,transactions!$D$2:$D$2601,"Sale") -> 2695 | E30: =SUMIFS(transactions!$N$2:$N$2601,transactions!$H$2:$H$2601,A30) -> 171340 | F30: =E30/E$38 -> 0.094587731 | G30: =SUMIFS(transactions!$P$2:$P$2601,transactions!$H$2:$H$2601,A30) -> 55310 | H30: =IF(E30=0,0,G30/E30) -> 0.32280845
A31: Pain Relief | B31: =COUNTIF(medicine_master!$C$2:$C$26,A31) -> 3 | C31: =B31/B$38 -> 0.12 | D31: =SUMIFS(transactions!$E$2:$E$2601,transactions!$H$2:$H$2601,A31,transactions!$D$2:$D$2601,"Sale") -> 4600 | E31: =SUMIFS(transactions!$N$2:$N$2601,transactions!$H$2:$H$2601,A31) -> 168520 | F31: =E31/E$38 -> 0.093030959 | G31: =SUMIFS(transactions!$P$2:$P$2601,transactions!$H$2:$H$2601,A31) -> 51070 | H31: =IF(E31=0,0,G31/E31) -> 0.30305008
A32: Dermatology | B32: =COUNTIF(medicine_master!$C$2:$C$26,A32) -> 2 | C32: =B32/B$38 -> 0.08 | D32: =SUMIFS(transactions!$E$2:$E$2601,transactions!$H$2:$H$2601,A32,transactions!$D$2:$D$2601,"Sale") -> 3105 | E32: =SUMIFS(transactions!$N$2:$N$2601,transactions!$H$2:$H$2601,A32) -> 162960 | F32: =E32/E$38 -> 0.089961578 | G32: =SUMIFS(transactions!$P$2:$P$2601,transactions!$H$2:$H$2601,A32) -> 52000 | H32: =IF(E32=0,0,G32/E32) -> 0.31909671
A33: Antibiotic | B33: =COUNTIF(medicine_master!$C$2:$C$26,A33) -> 2 | C33: =B33/B$38 -> 0.08 | D33: =SUMIFS(transactions!$E$2:$E$2601,transactions!$H$2:$H$2601,A33,transactions!$D$2:$D$2601,"Sale") -> 3060 | E33: =SUMIFS(transactions!$N$2:$N$2601,transactions!$H$2:$H$2601,A33) -> 138000 | F33: =E33/E$38 -> 0.076182485 | G33: =SUMIFS(transactions!$P$2:$P$2601,transactions!$H$2:$H$2601,A33) -> 41400 | H33: =IF(E33=0,0,G33/E33) -> 0.3
A34: First Aid | B34: =COUNTIF(medicine_master!$C$2:$C$26,A34) -> 3 | C34: =B34/B$38 -> 0.12 | D34: =SUMIFS(transactions!$E$2:$E$2601,transactions!$H$2:$H$2601,A34,transactions!$D$2:$D$2601,"Sale") -> 4025 | E34: =SUMIFS(transactions!$N$2:$N$2601,transactions!$H$2:$H$2601,A34) -> 132900 | F34: =E34/E$38 -> 0.073367045 | G34: =SUMIFS(transactions!$P$2:$P$2601,transactions!$H$2:$H$2601,A34) -> 40920 | H34: =IF(E34=0,0,G34/E34) -> 0.30790068
A35: Allergy | B35: =COUNTIF(medicine_master!$C$2:$C$26,A35) -> 3 | C35: =B35/B$38 -> 0.12 | D35: =SUMIFS(transactions!$E$2:$E$2601,transactions!$H$2:$H$2601,A35,transactions!$D$2:$D$2601,"Sale") -> 4420 | E35: =SUMIFS(transactions!$N$2:$N$2601,transactions!$H$2:$H$2601,A35) -> 107350 | F35: =E35/E$38 -> 0.059262244 | G35: =SUMIFS(transactions!$P$2:$P$2601,transactions!$H$2:$H$2601,A35) -> 36380 | H35: =IF(E35=0,0,G35/E35) -> 0.33889148
A36: Gastric | B36: =COUNTIF(medicine_master!$C$2:$C$26,A36) -> 2 | C36: =B36/B$38 -> 0.08 | D36: =SUMIFS(transactions!$E$2:$E$2601,transactions!$H$2:$H$2601,A36,transactions!$D$2:$D$2601,"Sale") -> 2945 | E36: =SUMIFS(transactions!$N$2:$N$2601,transactions!$H$2:$H$2601,A36) -> 90475 | F36: =E36/E$38 -> 0.049946451 | G36: =SUMIFS(transactions!$P$2:$P$2601,transactions!$H$2:$H$2601,A36) -> 28195 | H36: =IF(E36=0,0,G36/E36) -> 0.31163305
A37: Cardiac | B37: =COUNTIF(medicine_master!$C$2:$C$26,A37) -> 3 | C37: =B37/B$38 -> 0.12 | D37: =SUMIFS(transactions!$E$2:$E$2601,transactions!$H$2:$H$2601,A37,transactions!$D$2:$D$2601,"Sale") -> 4285 | E37: =SUMIFS(transactions!$N$2:$N$2601,transactions!$H$2:$H$2601,A37) -> 89775 | F37: =E37/E$38 -> 0.049560019 | G37: =SUMIFS(transactions!$P$2:$P$2601,transactions!$H$2:$H$2601,A37) -> 28925 | H37: =IF(E37=0,0,G37/E37) -> 0.32219437
A38: Total | B38: =SUM(B28:B37) -> 25 | C38: =SUM(C28:C37) -> 1 | D38: =SUM(D28:D37) -> 37285 | E38: =SUM(E28:E37) -> 1811440 | F38: =SUM(F28:F37) -> 1 | G38: =SUM(G28:G37) -> 538920 | H38: =IF(E38=0,0,G38/E38) -> 0.29750916
A41: 3. Monthly Sales Trend | C41: Pivot-style: Rows = Month, Values = Units, Revenue, Profit
A42: Month No. | B42: Month | C42: Units Sold | D42: Revenue | E42: Gross Profit | F42: Units Purchased | G42: Transactions
A43: 1 | B43: Jan 2026 | C43: =SUMIFS(transactions!$E$2:$E$2601,transactions!$J$2:$J$2601,A43,transactions!$D$2:$D$2601,"Sale") -> 3115 | D43: =SUMIFS(transactions!$N$2:$N$2601,transactions!$J$2:$J$2601,A43) -> 150690 | E43: =SUMIFS(transactions!$P$2:$P$2601,transactions!$J$2:$J$2601,A43) -> 44970 | F43: =SUMIFS(transactions!$E$2:$E$2601,transactions!$J$2:$J$2601,A43,transactions!$D$2:$D$2601,"Purchase") -> 1860 | G43: =COUNTIF(transactions!$J$2:$J$2601,A43) -> 208
A44: 2 | B44: Feb 2026 | C44: =SUMIFS(transactions!$E$2:$E$2601,transactions!$J$2:$J$2601,A44,transactions!$D$2:$D$2601,"Sale") -> 3255 | D44: =SUMIFS(transactions!$N$2:$N$2601,transactions!$J$2:$J$2601,A44) -> 157420 | E44: =SUMIFS(transactions!$P$2:$P$2601,transactions!$J$2:$J$2601,A44) -> 46935 | F44: =SUMIFS(transactions!$E$2:$E$2601,transactions!$J$2:$J$2601,A44,transactions!$D$2:$D$2601,"Purchase") -> 1895 | G44: =COUNTIF(transactions!$J$2:$J$2601,A44) -> 221
...

Sheet Insights
A1: Business Insights & Recommendations
A2: Every insight is tied to a number in the Analysis sheet. Figures reflect the dataset as provided (all of 2026).
A4: # | B4: Topic | C4: Insight | D4: Evidence
A5: 1 | B5: Total business volume | C5: The store recorded 2,600 transactions: 1,594 sales and 1,006 purchases. 37,285 units were sold against 23,595 units purchased, and each transaction averages 23.4 units. | D5: Analysis: KPIs, table 4
A6: 2 | B6: Revenue and profit | C6: Sales revenue is ₹1,811,440 with a gross profit of ₹538,920, a margin of 29.8%. Purchase spend in the data is ₹757,815. | D6: Analysis: KPIs
A7: 3 | B7: Best seller (volume) | C7: Glimepiride 2mg sold the most units: 2,050 units (5.5% of all units sold). | D7: Analysis: table 5
A8: 4 | B8: Best seller (value) | C8: Insulin Injection earns the most revenue: ₹378,000, which is 20.9% of total revenue from only 4.5% of units sold. It also gives the highest gross profit (₹100,800, 18.7% of all profit). | D8: Analysis: table 6
A9: 5 | B9: Best category | C9: Diabetes is the top category with ₹517,360 revenue (28.6% of total) from just 3 of 25 medicines (12% of the range). Cold & Cough follows with ₹232,760 (12.8%). | D9: Analysis: table 2
A10: 6 | B10: Volume vs value | C10: Cardiac is last in revenue (₹89,775, 5.0%) even though it sold 4,285 units, more than Dermatology or Antibiotic. Low unit prices, not low demand, explain its rank. | D10: Analysis: table 2
A11: 7 | B11: Monthly trend | C11: Revenue is fairly steady between ₹134,650 and ₹168,135 a month. Highest: November (₹168,135); lowest: December (₹134,650). Note that October-December rows are dated after the 5 Oct 2026 analysis date. | D11: Analysis: table 3
A12: 8 | B12: Restocking need | C12: Every one of the 25 medicines sold more units than were purchased in the data (37,285 sold vs 23,595 purchased, 1.58x), so the store appears to rely on opening stock that is not in the dataset. 9 medicines have a Sold/Purchased ratio of 1.75 or more; the highest are Glimepiride 2mg (2.72), Diclofenac Gel (2.60), Cetirizine 10mg (2.22), Azithromycin 500mg (2.20). | D12: Analysis: tables 7-8
A13: 9 | B13: Slow movers | C13: The slowest sellers are Calamine Lotion (1,160 units) and Bandage Roll (1,190 units). The gap to the top seller (2,050) is real but no medicine is truly dead stock: every medicine has at least 52 sale transactions. | D13: Analysis: table 9
A14: 10 | B14: Expiry risk | C14: No medicine is expired at the analysis date. The nearest expiry is Cough Syrup 100ml on 2027-02-20 (138 days away), and it is also one of the top 5 revenue medicines (₹104,760). 11 of 25 medicines expire within one year. | D14: Analysis: table 10; medicine_master
A15: 11 | B15: Transaction patterns | C15: All quantities are multiples of 5 between 5 and 50, which looks like standard pack or lot sizes, and no unusual outliers were found. 609 transactions are dated after the analysis date and should be confirmed with the data owner. | D15: Data_Cleaning: check 16
A17: Business Recommendations
A18: # | B18: Recommendation | C18: Action | D18: Supported by
A19: 1 | B19: Restock fast-selling medicines first | C19: Prioritise the 9 High-priority medicines, starting with Glimepiride 2mg, Diclofenac Gel, Cetirizine 10mg, Azithromycin 500mg. Set reorder points using real stock counts once available. | D19: Insight: Restocking need
A20: 2 | B20: Protect the diabetes range | C20: Keep Insulin Injection and the other Diabetes medicines always in stock: Diabetes brings 28.6% of revenue from 12% of the range. | D20: Insights: Best seller (value), Best category
A21: 3 | B21: Plan purchasing by value, not only volume | C21: Use revenue and margin together when ordering: Cardiac and Allergy sell many units but add little revenue. | D21: Insight: Volume vs value
A22: 4 | B22: Sell the nearest-expiry batches first | C22: Move Cough Syrup 100ml (expiry 2027-02-20) to the front of the shelf and review all medicines expiring within one year every month. | D22: Insight: Expiry risk
A23: 5 | B23: Review slow movers before reordering | C23: Check Calamine Lotion and Bandage Roll before the next order; they sell least but still sell steadily, so reduce quantity rather than stop buying. | D23: Insight: Slow movers
A24: 6 | B24: Track monthly sales for seasonal buying | C24: Monthly revenue is stable, so keep a month-by-month record and look for seasonal peaks (e.g. cold and cough medicines) once more than one year of data exists. | D24: Insight: Monthly trend
A25: 7 | B25: Add a stock-on-hand column to the data | C25: Record opening stock and current stock per medicine. This allows true low-stock alerts and stock value, which this dataset cannot provide. | D25: Limitation 1
A27: Limitations
A28: 1 | B28: No stock or opening-stock column exists, so low-stock items and stock value could not be calculated; restock need is estimated from the Sold/Purchased ratio.
A29: 2 | B29: The data has one batch and one expiry date per medicine, so expiry risk is per medicine, not per batch.
A30: 3 | B30: The data covers a single year, so seasonality cannot be confirmed.

Sheet Data_Cleaning
A1: Data Cleaning & Validation Checks
A2: Each result is a live formula. PASS = result equals the expected value. REVIEW = needs a human decision (not an error). FAIL = a data problem.
A4: # | B4: Check | C4: Result | D4: Expected | E4: Status | F4: What it means / how it is checked
A5: 1 | B5: Rows in transactions sheet | C5: =COUNTA(transactions!$A$2:$A$2601) -> 2600 | D5: 2600 | E5: =IF(C5=D5,"PASS","FAIL") -> PASS | F5: Matches the 2,600 rows in the source file (nothing lost while loading).
A6: 2 | B6: Missing values - transactions | C6: =COUNTBLANK(transactions!$A$2:$E$2601) -> 0 | D6: 0 | E6: =IF(C6=D6,"PASS","FAIL") -> PASS | F6: COUNTBLANK counts empty cells in the 5 original columns.
A7: 3 | B7: Missing values - medicine_master | C7: =COUNTBLANK(medicine_master!$A$2:$I$26) -> 0 | D7: 0 | E7: =IF(C7=D7,"PASS","FAIL") -> PASS | F7: COUNTBLANK counts empty cells in the 9 original columns.
A8: 4 | B8: Duplicate Transaction_IDs | C8: =SUMPRODUCT((COUNTIF(transactions!$A$2:$A$2601,transactions!$A$2:$A$2601)>1)*1) -> 0 | D8: 0 | E8: =IF(C8=D8,"PASS","FAIL") -> PASS | F8: Counts IDs that appear more than once. 0 = every Transaction_ID is unique.
A9: 5 | B9: Duplicate Medicine_IDs | C9: =SUMPRODUCT((COUNTIF(medicine_master!$A$2:$A$26,medicine_master!$A$2:$A$26)>1)*1) -> 0 | D9: 0 | E9: =IF(C9=D9,"PASS","FAIL") -> PASS | F9: Counts Medicine_IDs that appear more than once in medicine_master.
A10: 6 | B10: Invalid Medicine_ID references | C10: =COUNTIF(transactions!$F$2:$F$2601,"Invalid") -> 0 | D10: 0 | E10: =IF(C10=D10,"PASS","FAIL") -> PASS | F10: Transactions whose Medicine_ID is not found in medicine_master (ID_Check column).
A11: 7 | B11: Invalid quantities (<=0 or not a number) | C11: =COUNTIF(transactions!$E$2:$E$2601,"<=0")+ROWS(transactions!$E$2:$E$2601)-COUNT(transactions!$E$2:$E$2601) -> 0 | D11: 0 | E11: =IF(C11=D11,"PASS","FAIL") -> PASS | F11: Quantity must be a positive number.
A12: 8 | B12: Invalid dates (not real dates) | C12: =ROWS(transactions!$B$2:$B$2601)-COUNT(transactions!$B$2:$B$2601) -> 0 | D12: 0 | E12: =IF(C12=D12,"PASS","FAIL") -> PASS | F12: COUNT only counts real dates/numbers, so text dates would show up here.
A13: 9 | B13: Dates outside the year 2026 | C13: =ROWS(transactions!$I$2:$I$2601)-COUNTIF(transactions!$I$2:$I$2601,2026) -> 0 | D13: 0 | E13: =IF(C13=D13,"PASS","FAIL") -> PASS | F13: Confirms all transactions belong to 2026 (monthly analysis relies on this).
A14: 10 | B14: Invalid Transaction_Type values | C14: =ROWS(transactions!$D$2:$D$2601)-COUNTIF(transactions!$D$2:$D$2601,"Sale")-COUNTIF(transactions!$D$2:$D$2601,"Purchase") -> 0 | D14: 0 | E14: =IF(C14=D14,"PASS","FAIL") -> PASS | F14: Only "Sale" and "Purchase" are expected.
A15: 11 | B15: Invalid prices (<=0) in medicine_master | C15: =COUNTIF(medicine_master!$G$2:$G$26,"<=0")+COUNTIF(medicine_master!$H$2:$H$26,"<=0")+COUNTIF(medicine_master!$I$2:$I$26,"<=0") -> 0 | D15: 0 | E15: =IF(C15=D15,"PASS","FAIL") -> PASS | F15: Purchase_Rate, MRP and Selling_Rate must all be positive.
A16: 12 | B16: Price logic violations | C16: =SUMPRODUCT(--((medicine_master!$G$2:$G$26>=medicine_master!$I$2:$I$26)+(medicine_master!$I$2:$I$26>medicine_master!$H$2:$H$26)>0)) -> 0 | D16: 0 | E16: =IF(C16=D16,"PASS","FAIL") -> PASS | F16: Flags medicines where Purchase_Rate >= Selling_Rate (loss-making) or Selling_Rate > MRP (illegal).
A17: 13 | B17: Names/categories with extra spaces | C17: =SUMPRODUCT(--(LEN(medicine_master!$B$2:$B$26)<>LEN(TRIM(medicine_master!$B$2:$B$26))))+SUMPRODUCT(--(LEN(medicine_master!$C$2:$C$26)<>LEN(TRIM(medicine_master!$C$2:$C$26)))) -> 0 | D17: 0 | E17: =IF(C17=D17,"PASS","FAIL") -> PASS | F17: Compares text length with and without TRIM; catches hidden spaces that break lookups.
A18: 14 | B18: Distinct category names | C18: =SUMPRODUCT(1/COUNTIF(medicine_master!$C$2:$C$26,medicine_master!$C$2:$C$26)) -> 10 | D18: 10 | E18: =IF(C18=D18,"PASS","FAIL") -> PASS | F18: 10 categories expected; a higher number would mean spelling variants (e.g. "Gastric" vs "gastric").
A19: 15 | B19: Medicines already expired at analysis date | C19: =COUNTIF(medicine_master!$L$2:$L$26,"<0") -> 0 | D19: 0 | E19: =IF(C19=D19,"PASS","REVIEW") -> PASS | F19: Expired stock should be removed from sale.
A20: 16 | B20: Transactions dated after the analysis date | C20: =COUNTIF(transactions!$B$2:$B$2601,">"&Overview!$C$22) -> 609 | D20: 0 | E20: =IF(C20=D20,"PASS","REVIEW") -> REVIEW | F20: Dates run to 31 Dec 2026 but analysis date is 5 Oct 2026. Rows were KEPT (not deleted) because the data may be a full-year dataset; confirm with the data owner.
A21: 17 | B21: Total revenue vs source file (₹) | C21: =ROUND(SUM(transactions!$N$2:$N$2601),0) -> 1811440 | D21: 1811440 | E21: =IF(C21=D21,"PASS","FAIL") -> PASS | F21: Cross-check: Sum of Revenue column in medical_store_transactions_combined.csv (provided by user).
A22: 18 | B22: Total cost of goods sold vs source file (₹) | C22: =ROUND(SUM(transactions!$O$2:$O$2601),0) -> 1272520 | D22: 1272520 | E22: =IF(C22=D22,"PASS","FAIL") -> PASS | F22: Cross-check: Sum of Cost column in medical_store_transactions_combined.csv (provided by user).
B24: Summary of cleaning actions
B25: 1. Loaded transactions.csv and medicine_master.csv; the third file (medical_store_transactions_combined.csv) was used only to verify revenue and cost totals.
B26: 2. Converted Date and Expiry_Date from text to real dates so that month, year and days-to-expiry can be calculated.
B27: 3. No rows were deleted or edited: no missing values, duplicates, invalid IDs, invalid quantities or invalid prices were found.
B28: 4. Added helper columns: ID_Check (lookup validity) in transactions; calculated columns for sales amount, cost, profit, month, expiry status, restock priority.
B29: 5. One item needs a decision: 609 transactions are dated after the analysis date (see check #16).

Sheet transactions
A1: Transaction_ID | B1: Date | C1: Medicine_ID | D1: Transaction_Type | E1: Quantity | F1: ID_Check | G1: Medicine_Name | H1: Category | I1: Year | J1: Month_Num | K1: Month_Name | L1: Selling_Rate | M1: Purchase_Rate | N1: Sales_Amount | O1: Cost_of_Goods_Sold | P1: Gross_Profit | Q1: Purchase_Spend | S1: Columns A-E = original data. Columns F-Q = calculated (formulas).
A2: T00001 | B2: 46336 | C2: M022 | D2: Purchase | E2: 5 | F2: =IF(COUNTIF(medicine_master!$A$2:$A$26,C2)>0,"Valid","Invalid") -> Valid | G2: =IFERROR(INDEX(medicine_master!$B$2:$B$26,MATCH($C2,medicine_master!$A$2:$A$26,0)),"Not found") -> Levocetirizine 5mg | H2: =IFERROR(INDEX(medicine_master!$C$2:$C$26,MATCH($C2,medicine_master!$A$2:$A$26,0)),"Not found") -> Allergy | I2: =YEAR(B2) -> 2026 | J2: =MONTH(B2) -> 11 | K2: =TEXT(B2,"mmm") -> Nov | L2: =IFERROR(INDEX(medicine_master!$I$2:$I$26,MATCH($C2,medicine_master!$A$2:$A$26,0)),0) -> 22 | M2: =IFERROR(INDEX(medicine_master!$G$2:$G$26,MATCH($C2,medicine_master!$A$2:$A$26,0)),0) -> 14 | N2: =IF(D2="Sale",E2*L2,0) -> 0 | O2: =IF(D2="Sale",E2*M2,0) -> 0 | P2: =N2-O2 -> 0 | Q2: =IF(D2="Purchase",E2*M2,0) -> 70
A3: T00002 | B3: 46081 | C3: M010 | D3: Purchase | E3: 50 | F3: =IF(COUNTIF(medicine_master!$A$2:$A$26,C3)>0,"Valid","Invalid") -> Valid | G3: =IFERROR(INDEX(medicine_master!$B$2:$B$26,MATCH($C3,medicine_master!$A$2:$A$26,0)),"Not found") -> Pantoprazole 40mg | H3: =IFERROR(INDEX(medicine_master!$C$2:$C$26,MATCH($C3,medicine_master!$A$2:$A$26,0)),"Not found") -> Gastric | I3: =YEAR(B3) -> 2026 | J3: =MONTH(B3) -> 2 | K3: =TEXT(B3,"mmm") -> Feb | L3: =IFERROR(INDEX(medicine_master!$I$2:$I$26,MATCH($C3,medicine_master!$A$2:$A$26,0)),0) -> 35 | M3: =IFERROR(INDEX(medicine_master!$G$2:$G$26,MATCH($C3,medicine_master!$A$2:$A$26,0)),0) -> 24 | N3: =IF(D3="Sale",E3*L3,0) -> 0 | O3: =IF(D3="Sale",E3*M3,0) -> 0 | P3: =N3-O3 -> 0 | Q3: =IF(D3="Purchase",E3*M3,0) -> 1200
A4: T00003 | B4: 46293 | C4: M015 | D4: Sale | E4: 20 | F4: =IF(COUNTIF(medicine_master!$A$2:$A$26,C4)>0,"Valid","Invalid") -> Valid | G4: =IFERROR(INDEX(medicine_master!$B$2:$B$26,MATCH($C4,medicine_master!$A$2:$A$26,0)),"Not found") -> Antiseptic Liquid 100ml | H4: =IFERROR(INDEX(medicine_master!$C$2:$C$26,MATCH($C4,medicine_master!$A$2:$A$26,0)),"Not found") -> First Aid | I4: =YEAR(B4) -> 2026 | J4: =MONTH(B4) -> 9 | K4: =TEXT(B4,"mmm") -> Sep | L4: =IFERROR(INDEX(medicine_master!$I$2:$I$26,MATCH($C4,medicine_master!$A$2:$A$26,0)),0) -> 65 | M4: =IFERROR(INDEX(medicine_master!$G$2:$G$26,MATCH($C4,medicine_master!$A$2:$A$26,0)),0) -> 48 | N4: =IF(D4="Sale",E4*L4,0) -> 1300 | O4: =IF(D4="Sale",E4*M4,0) -> 960 | P4: =N4-O4 -> 340 | Q4: =IF(D4="Purchase",E4*M4,0) -> 0
A5: T00004 | B5: 46266 | C5: M025 | D5: Purchase | E5: 25 | F5: =IF(COUNTIF(medicine_master!$A$2:$A$26,C5)>0,"Valid","Invalid") -> Valid | G5: =IFERROR(INDEX(medicine_master!$B$2:$B$26,MATCH($C5,medicine_master!$A$2:$A$26,0)),"Not found") -> Aspirin 75mg | H5: =IFERROR(INDEX(medicine_master!$C$2:$C$26,MATCH($C5,medicine_master!$A$2:$A$26,0)),"Not found") -> Cardiac | I5: =YEAR(B5) -> 2026 | J5: =MONTH(B5) -> 9 | K5: =TEXT(B5,"mmm") -> Sep | L5: =IFERROR(INDEX(medicine_master!$I$2:$I$26,MATCH($C5,medicine_master!$A$2:$A$26,0)),0) -> 15 | M5: =IFERROR(INDEX(medicine_master!$G$2:$G$26,MATCH($C5,medicine_master!$A$2:$A$26,0)),0) -> 10 | N5: =IF(D5="Sale",E5*L5,0) -> 0 | O5: =IF(D5="Sale",E5*M5,0) -> 0 | P5: =N5-O5 -> 0 | Q5: =IF(D5="Purchase",E5*M5,0) -> 250
A6: T00005 | B6: 46043 | C6: M009 | D6: Purchase | E6: 50 | F6: =IF(COUNTIF(medicine_master!$A$2:$A$26,C6)>0,"Valid","Invalid") -> Valid | G6: =IFERROR(INDEX(medicine_master!$B$2:$B$26,MATCH($C6,medicine_master!$A$2:$A$26,0)),"Not found") -> Omeprazole 20mg | H6: =IFERROR(INDEX(medicine_master!$C$2:$C$26,MATCH($C6,medicine_master!$A$2:$A$26,0)),"Not found") -> Gastric | I6: =YEAR(B6) -> 2026 | J6: =MONTH(B6) -> 1 | K6: =TEXT(B6,"mmm") -> Jan | L6: =IFERROR(INDEX(medicine_master!$I$2:$I$26,MATCH($C6,medicine_master!$A$2:$A$26,0)),0) -> 26 | M6: =IFERROR(INDEX(medicine_master!$G$2:$G$26,MATCH($C6,medicine_master!$A$2:$A$26,0)),0) -> 18 | N6: =IF(D6="Sale",E6*L6,0) -> 0 | O6: =IF(D6="Sale",E6*M6,0) -> 0 | P6: =N6-O6 -> 0 | Q6: =IF(D6="Purchase",E6*M6,0) -> 900
A7: T00006 | B7: 46338 | C7: M014 | D7: Sale | E7: 15 | F7: =IF(COUNTIF(medicine_master!$A$2:$A$26,C7)>0,"Valid","Invalid") -> Valid | G7: =IFERROR(INDEX(medicine_master!$B$2:$B$26,MATCH($C7,medicine_master!$A$2:$A$26,0)),"Not found") -> Atorvastatin 10mg | H7: =IFERROR(INDEX(medicine_master!$C$2:$C$26,MATCH($C7,medicine_master!$A$2:$A$26,0)),"Not found") -> Cardiac | I7: =YEAR(B7) -> 2026 | J7: =MONTH(B7) -> 11 | K7: =TEXT(B7,"mmm") -> Nov | L7: =IFERROR(INDEX(medicine_master!$I$2:$I$26,MATCH($C7,medicine_master!$A$2:$A$26,0)),0) -> 28 | M7: =IFERROR(INDEX(medicine_master!$G$2:$G$26,MATCH($C7,medicine_master!$A$2:$A$26,0)),0) -> 19 | N7: =IF(D7="Sale",E7*L7,0) -> 420 | O7: =IF(D7="Sale",E7*M7,0) -> 285 | P7: =N7-O7 -> 135 | Q7: =IF(D7="Purchase",E7*M7,0) -> 0
A8: T00007 | B8: 46075 | C8: M002 | D8: Sale | E8: 20 | F8: =IF(COUNTIF(medicine_master!$A$2:$A$26,C8)>0,"Valid","Invalid") -> Valid | G8: =IFERROR(INDEX(medicine_master!$B$2:$B$26,MATCH($C8,medicine_master!$A$2:$A$26,0)),"Not found") -> Ibuprofen 400mg | H8: =IFERROR(INDEX(medicine_master!$C$2:$C$26,MATCH($C8,medicine_master!$A$2:$A$26,0)),"Not found") -> Pain Relief | I8: =YEAR(B8) -> 2026 | J8: =MONTH(B8) -> 2 | K8: =TEXT(B8,"mmm") -> Feb | L8: =IFERROR(INDEX(medicine_master!$I$2:$I$26,MATCH($C8,medicine_master!$A$2:$A$26,0)),0) -> 30 | M8: =IFERROR(INDEX(medicine_master!$G$2:$G$26,MATCH($C8,medicine_master!$A$2:$A$26,0)),0) -> 22 | N8: =IF(D8="Sale",E8*L8,0) -> 600 | O8: =IF(D8="Sale",E8*M8,0) -> 440 | P8: =N8-O8 -> 160 | Q8: =IF(D8="Purchase",E8*M8,0) -> 0
A9: T00008 | B9: 46286 | C9: M015 | D9: Purchase | E9: 20 | F9: =IF(COUNTIF(medicine_master!$A$2:$A$26,C9)>0,"Valid","Invalid") -> Valid | G9: =IFERROR(INDEX(medicine_master!$B$2:$B$26,MATCH($C9,medicine_master!$A$2:$A$26,0)),"Not found") -> Antiseptic Liquid 100ml | H9: =IFERROR(INDEX(medicine_master!$C$2:$C$26,MATCH($C9,medicine_master!$A$2:$A$26,0)),"Not found") -> First Aid | I9: =YEAR(B9) -> 2026 | J9: =MONTH(B9) -> 9 | K9: =TEXT(B9,"mmm") -> Sep | L9: =IFERROR(INDEX(medicine_master!$I$2:$I$26,MATCH($C9,medicine_master!$A$2:$A$26,0)),0) -> 65 | M9: =IFERROR(INDEX(medicine_master!$G$2:$G$26,MATCH($C9,medicine_master!$A$2:$A$26,0)),0) -> 48 | N9: =IF(D9="Sale",E9*L9,0) -> 0 | O9: =IF(D9="Sale",E9*M9,0) -> 0 | P9: =N9-O9 -> 0 | Q9: =IF(D9="Purchase",E9*M9,0) -> 960
A10: T00009 | B10: 46072 | C10: M008 | D10: Sale | E10: 20 | F10: =IF(COUNTIF(medicine_master!$A$2:$A$26,C10)>0,"Valid","Invalid") -> Valid | G10: =IFERROR(INDEX(medicine_master!$B$2:$B$26,MATCH($C10,medicine_master!$A$2:$A$26,0)),"Not found") -> Multivitamin Tablets | H10: =IFERROR(INDEX(medicine_master!$C$2:$C$26,MATCH($C10,medicine_master!$A$2:$A$26,0)),"Not found") -> Vitamin | I10: =YEAR(B10) -> 2026 | J10: =MONTH(B10) -> 2 | K10: =TEXT(B10,"mmm") -> Feb | L10: =IFERROR(INDEX(medicine_master!$I$2:$I$26,MATCH($C10,medicine_master!$A$2:$A$26,0)),0) -> 105 | M10: =IFERROR(INDEX(medicine_master!$G$2:$G$26,MATCH($C10,medicine_master!$A$2:$A$26,0)),0) -> 72 | N10: =IF(D10="Sale",E10*L10,0) -> 2100 | O10: =IF(D10="Sale",E10*M10,0) -> 1440 | P10: =N10-O10 -> 660 | Q10: =IF(D10="Purchase",E10*M10,0) -> 0
A11: T00010 | B11: 46076 | C11: M010 | D11: Sale | E11: 5 | F11: =IF(COUNTIF(medicine_master!$A$2:$A$26,C11)>0,"Valid","Invalid") -> Valid | G11: =IFERROR(INDEX(medicine_master!$B$2:$B$26,MATCH($C11,medicine_master!$A$2:$A$26,0)),"Not found") -> Pantoprazole 40mg | H11: =IFERROR(INDEX(medicine_master!$C$2:$C$26,MATCH($C11,medicine_master!$A$2:$A$26,0)),"Not found") -> Gastric | I11: =YEAR(B11) -> 2026 | J11: =MONTH(B11) -> 2 | K11: =TEXT(B11,"mmm") -> Feb | L11: =IFERROR(INDEX(medicine_master!$I$2:$I$26,MATCH($C11,medicine_master!$A$2:$A$26,0)),0) -> 35 | M11: =IFERROR(INDEX(medicine_master!$G$2:$G$26,MATCH($C11,medicine_master!$A$2:$A$26,0)),0) -> 24 | N11: =IF(D11="Sale",E11*L11,0) -> 175 | O11: =IF(D11="Sale",E11*M11,0) -> 120 | P11: =N11-O11 -> 55 | Q11: =IF(D11="Purchase",E11*M11,0) -> 0
A12: T00011 | B12: 46240 | C12: M012 | D12: Sale | E12: 40 | F12: =IF(COUNTIF(medicine_master!$A$2:$A$26,C12)>0,"Valid","Invalid") -> Valid | G12: =IFERROR(INDEX(medicine_master!$B$2:$B$26,MATCH($C12,medicine_master!$A$2:$A$26,0)),"Not found") -> Glimepiride 2mg | H12: =IFERROR(INDEX(medicine_master!$C$2:$C$26,MATCH($C12,medicine_master!$A$2:$A$26,0)),"Not found") -> Diabetes | I12: =YEAR(B12) -> 2026 | J12: =MONTH(B12) -> 8 | K12: =TEXT(B12,"mmm") -> Aug | L12: =IFERROR(INDEX(medicine_master!$I$2:$I$26,MATCH($C12,medicine_master!$A$2:$A$26,0)),0) -> 52 | M12: =IFERROR(INDEX(medicine_master!$G$2:$G$26,MATCH($C12,medicine_master!$A$2:$A$26,0)),0) -> 38 | N12: =IF(D12="Sale",E12*L12,0) -> 2080 | O12: =IF(D12="Sale",E12*M12,0) -> 1520 | P12: =N12-O12 -> 560 | Q12: =IF(D12="Purchase",E12*M12,0) -> 0
A13: T00012 | B13: 46292 | C13: M016 | D13: Purchase | E13: 25 | F13: =IF(COUNTIF(medicine_master!$A$2:$A$26,C13)>0,"Valid","Invalid") -> Valid | G13: =IFERROR(INDEX(medicine_master!$B$2:$B$26,MATCH($C13,medicine_master!$A$2:$A$26,0)),"Not found") -> Bandage Roll | H13: =IFERROR(INDEX(medicine_master!$C$2:$C$26,MATCH($C13,medicine_master!$A$2:$A$26,0)),"Not found") -> First Aid | I13: =YEAR(B13) -> 2026 | J13: =MONTH(B13) -> 9 | K13: =TEXT(B13,"mmm") -> Sep | L13: =IFERROR(INDEX(medicine_master!$I$2:$I$26,MATCH($C13,medicine_master!$A$2:$A$26,0)),0) -> 25 | M13: =IFERROR(INDEX(medicine_master!$G$2:$G$26,MATCH($C13,medicine_master!$A$2:$A$26,0)),0) -> 15 | N13: =IF(D13="Sale",E13*L13,0) -> 0 | O13: =IF(D13="Sale",E13*M13,0) -> 0 | P13: =N13-O13 -> 0 | Q13: =IF(D13="Purchase",E13*M13,0) -> 375
... A2601: T02600 | B2601: 46282 | C2601: M025 | D2601: Sale | E2601: 50 | F2601: =IF(COUNTIF(medicine_master!$A$2:$A$26,C2601)>0,"Valid","Invalid") -> Valid | G2601: =IFERROR(INDEX(medicine_master!$B$2:$B$26,MATCH($C2601,medicine_master!$A$2:$A$26,0)),"Not found") -> Aspirin 75mg | H2601: =IFERROR(INDEX(medicine_master!$C$2:$C$26,MATCH($C2601,medicine_master!$A$2:$A$26,0)),"Not found") -> Cardiac | I2601: =YEAR(B2601) -> 2026 | J2601: =MONTH(B2601) -> 9 | K2601: =TEXT(B2601,"mmm") -> Sep | L2601: =IFERROR(INDEX(medicine_master!$I$2:$I$26,MATCH($C2601,medicine_master!$A$2:$A$26,0)),0) -> 15 | M2601: =IFERROR(INDEX(medicine_master!$G$2:$G$26,MATCH($C2601,medicine_master!$A$2:$A$26,0)),0) -> 10 | N2601: =IF(D2601="Sale",E2601*L2601,0) -> 750 | O2601: =IF(D2601="Sale",E2601*M2601,0) -> 500 | P2601: =N2601-O2601 -> 250 | Q2601: =IF(D2601="Purchase",E2601*M2601,0) -> 0

Sheet medicine_master
A1: Medicine_ID | B1: Medicine_Name | C1: Category | D1: Batch_No | E1: Expiry_Date | F1: Supplier | G1: Purchase_Rate | H1: MRP | I1: Selling_Rate | J1: Margin_per_Unit | K1: Margin_Pct | L1: Days_to_Expiry | M1: Expiry_Status | N1: Units_Purchased | O1: Units_Sold | P1: Net_Movement | Q1: Sold_to_Purchased_Ratio | R1: Sales_Revenue | S1: Gross_Profit | T1: Restock_Priority | U1: Units_Rank | V1: Revenue_Rank | W1: Sales_Category | Y1: Columns A-I = original data. Columns J-W = calculated (formulas).
A2: M001 | B2: Paracetamol 500mg | C2: Pain Relief | D2: B101 | E2: 46520 | F2: ABC Pharma | G2: 12 | H2: 20 | I2: 18 | J2: =I2-G2 -> 6 | K2: =IF(I2=0,0,J2/I2) -> 0.33333333 | L2: =E2-Overview!$C$22 -> 220 | M2: =IF(L2<0,"Expired",IF(L2<=Overview!$C$23,"Critical",IF(L2<=Overview!$C$24,"Expiring Soon",IF(L2<=Overview!$C$25,"Watch","Safe")))) -> Watch | N2: =SUMIFS(transactions!$E$2:$E$2601,transactions!$C$2:$C$2601,$A2,transactions!$D$2:$D$2601,"Purchase") -> 1175 | O2: =SUMIFS(transactions!$E$2:$E$2601,transactions!$C$2:$C$2601,$A2,transactions!$D$2:$D$2601,"Sale") -> 1415 | P2: =N2-O2 -> -240 | Q2: =IF(N2=0,0,O2/N2) -> 1.2042553 | R2: =SUMIFS(transactions!$N$2:$N$2601,transactions!$C$2:$C$2601,$A2) -> 25470 | S2: =SUMIFS(transactions!$P$2:$P$2601,transactions!$C$2:$C$2601,$A2) -> 8490 | T2: =IF(Q2>=Overview!$C$26,"High",IF(Q2>=Overview!$C$27,"Medium","Low")) -> Low | U2: =RANK(O2,$O$2:$O$26) -> 15 | V2: =RANK(R2,$R$2:$R$26) -> 22 | W2: =IF(O2>=PERCENTILE($O$2:$O$26,0.75),"Fast",IF(O2<=PERCENTILE($O$2:$O$26,0.25),"Slow","Medium")) -> Medium
A3: M002 | B3: Ibuprofen 400mg | C3: Pain Relief | D3: B102 | E3: 46853 | F3: Medico Ltd | G3: 22 | H3: 35 | I3: 30 | J3: =I3-G3 -> 8 | K3: =IF(I3=0,0,J3/I3) -> 0.26666667 | L3: =E3-Overview!$C$22 -> 553 | M3: =IF(L3<0,"Expired",IF(L3<=Overview!$C$23,"Critical",IF(L3<=Overview!$C$24,"Expiring Soon",IF(L3<=Overview!$C$25,"Watch","Safe")))) -> Safe | N3: =SUMIFS(transactions!$E$2:$E$2601,transactions!$C$2:$C$2601,$A3,transactions!$D$2:$D$2601,"Purchase") -> 1005 | O3: =SUMIFS(transactions!$E$2:$E$2601,transactions!$C$2:$C$2601,$A3,transactions!$D$2:$D$2601,"Sale") -> 1285 | P3: =N3-O3 -> -280 | Q3: =IF(N3=0,0,O3/N3) -> 1.278607 | R3: =SUMIFS(transactions!$N$2:$N$2601,transactions!$C$2:$C$2601,$A3) -> 38550 | S3: =SUMIFS(transactions!$P$2:$P$2601,transactions!$C$2:$C$2601,$A3) -> 10280 | T3: =IF(Q3>=Overview!$C$26,"High",IF(Q3>=Overview!$C$27,"Medium","Low")) -> Low | U3: =RANK(O3,$O$2:$O$26) -> 22 | V3: =RANK(R3,$R$2:$R$26) -> 15 | W3: =IF(O3>=PERCENTILE($O$2:$O$26,0.75),"Fast",IF(O3<=PERCENTILE($O$2:$O$26,0.25),"Slow","Medium")) -> Slow
A4: M003 | B4: Cetirizine 10mg | C4: Allergy | D4: B103 | E4: 46688 | F4: XYZ Pharma | G4: 8 | H4: 15 | I4: 13 | J4: =I4-G4 -> 5 | K4: =IF(I4=0,0,J4/I4) -> 0.38461538 | L4: =E4-Overview!$C$22 -> 388 | M4: =IF(L4<0,"Expired",IF(L4<=Overview!$C$23,"Critical",IF(L4<=Overview!$C$24,"Expiring Soon",IF(L4<=Overview!$C$25,"Watch","Safe")))) -> Safe | N4: =SUMIFS(transactions!$E$2:$E$2601,transactions!$C$2:$C$2601,$A4,transactions!$D$2:$D$2601,"Purchase") -> 695 | O4: =SUMIFS(transactions!$E$2:$E$2601,transactions!$C$2:$C$2601,$A4,transactions!$D$2:$D$2601,"Sale") -> 1540 | P4: =N4-O4 -> -845 | Q4: =IF(N4=0,0,O4/N4) -> 2.2158273 | R4: =SUMIFS(transactions!$N$2:$N$2601,transactions!$C$2:$C$2601,$A4) -> 20020 | S4: =SUMIFS(transactions!$P$2:$P$2601,transactions!$C$2:$C$2601,$A4) -> 7700 | T4: =IF(Q4>=Overview!$C$26,"High",IF(Q4>=Overview!$C$27,"Medium","Low")) -> High | U4: =RANK(O4,$O$2:$O$26) -> 8 | V4: =RANK(R4,$R$2:$R$26) -> 23 | W4: =IF(O4>=PERCENTILE($O$2:$O$26,0.75),"Fast",IF(O4<=PERCENTILE($O$2:$O$26,0.25),"Slow","Medium")) -> Medium
A5: M004 | B5: Azithromycin 500mg | C5: Antibiotic | D5: B104 | E5: 46524 | F5: ABC Pharma | G5: 35 | H5: 55 | I5: 50 | J5: =I5-G5 -> 15 | K5: =IF(I5=0,0,J5/I5) -> 0.3 | L5: =E5-Overview!$C$22 -> 224 | M5: =IF(L5<0,"Expired",IF(L5<=Overview!$C$23,"Critical",IF(L5<=Overview!$C$24,"Expiring Soon",IF(L5<=Overview!$C$25,"Watch","Safe")))) -> Watch | N5: =SUMIFS(transactions!$E$2:$E$2601,transactions!$C$2:$C$2601,$A5,transactions!$D$2:$D$2601,"Purchase") -> 710 | O5: =SUMIFS(transactions!$E$2:$E$2601,transactions!$C$2:$C$2601,$A5,transactions!$D$2:$D$2601,"Sale") -> 1560 | P5: =N5-O5 -> -850 | Q5: =IF(N5=0,0,O5/N5) -> 2.1971831 | R5: =SUMIFS(transactions!$N$2:$N$2601,transactions!$C$2:$C$2601,$A5) -> 78000 | S5: =SUMIFS(transactions!$P$2:$P$2601,transactions!$C$2:$C$2601,$A5) -> 23400 | T5: =IF(Q5>=Overview!$C$26,"High",IF(Q5>=Overview!$C$27,"Medium","Low")) -> High | U5: =RANK(O5,$O$2:$O$26) -> 6 | V5: =RANK(R5,$R$2:$R$26) -> 9 | W5: =IF(O5>=PERCENTILE($O$2:$O$26,0.75),"Fast",IF(O5<=PERCENTILE($O$2:$O$26,0.25),"Slow","Medium")) -> Fast
A6: M005 | B6: Amoxicillin 500mg | C6: Antibiotic | D6: B105 | E6: 46489 | F6: HealthCare Labs | G6: 28 | H6: 45 | I6: 40 | J6: =I6-G6 -> 12 | K6: =IF(I6=0,0,J6/I6) -> 0.3 | L6: =E6-Overview!$C$22 -> 189 | M6: =IF(L6<0,"Expired",IF(L6<=Overview!$C$23,"Critical",IF(L6<=Overview!$C$24,"Expiring Soon",IF(L6<=Overview!$C$25,"Watch","Safe")))) -> Watch | N6: =SUMIFS(transactions!$E$2:$E$2601,transactions!$C$2:$C$2601,$A6,transactions!$D$2:$D$2601,"Purchase") -> 985 | O6: =SUMIFS(transactions!$E$2:$E$2601,transactions!$C$2:$C$2601,$A6,transactions!$D$2:$D$2601,"Sale") -> 1500 | P6: =N6-O6 -> -515 | Q6: =IF(N6=0,0,O6/N6) -> 1.5228426 | R6: =SUMIFS(transactions!$N$2:$N$2601,transactions!$C$2:$C$2601,$A6) -> 60000 | S6: =SUMIFS(transactions!$P$2:$P$2601,transactions!$C$2:$C$2601,$A6) -> 18000 | T6: =IF(Q6>=Overview!$C$26,"High",IF(Q6>=Overview!$C$27,"Medium","Low")) -> Medium | U6: =RANK(O6,$O$2:$O$26) -> 9 | V6: =RANK(R6,$R$2:$R$26) -> 11 | W6: =IF(O6>=PERCENTILE($O$2:$O$26,0.75),"Fast",IF(O6<=PERCENTILE($O$2:$O$26,0.25),"Slow","Medium")) -> Medium
A7: M006 | B7: Cough Syrup 100ml | C7: Cold & Cough | D7: B106 | E7: 46438 | F7: Medico Ltd | G7: 52 | H7: 80 | I7: 72 | J7: =I7-G7 -> 20 | K7: =IF(I7=0,0,J7/I7) -> 0.27777778 | L7: =E7-Overview!$C$22 -> 138 | M7: =IF(L7<0,"Expired",IF(L7<=Overview!$C$23,"Critical",IF(L7<=Overview!$C$24,"Expiring Soon",IF(L7<=Overview!$C$25,"Watch","Safe")))) -> Expiring Soon | N7: =SUMIFS(transactions!$E$2:$E$2601,transactions!$C$2:$C$2601,$A7,transactions!$D$2:$D$2601,"Purchase") -> 755 | O7: =SUMIFS(transactions!$E$2:$E$2601,transactions!$C$2:$C$2601,$A7,transactions!$D$2:$D$2601,"Sale") -> 1455 | P7: =N7-O7 -> -700 | Q7: =IF(N7=0,0,O7/N7) -> 1.9271523 | R7: =SUMIFS(transactions!$N$2:$N$2601,transactions!$C$2:$C$2601,$A7) -> 104760 | S7: =SUMIFS(transactions!$P$2:$P$2601,transactions!$C$2:$C$2601,$A7) -> 29100 | T7: =IF(Q7>=Overview!$C$26,"High",IF(Q7>=Overview!$C$27,"Medium","Low")) -> High | U7: =RANK(O7,$O$2:$O$26) -> 14 | V7: =RANK(R7,$R$2:$R$26) -> 5 | W7: =IF(O7>=PERCENTILE($O$2:$O$26,0.75),"Fast",IF(O7<=PERCENTILE($O$2:$O$26,0.25),"Slow","Medium")) -> Medium
A8: M007 | B8: Vitamin C 500mg | C8: Vitamin | D8: B107 | E8: 47032 | F8: Wellness Pharma | G8: 14 | H8: 25 | I8: 22 | J8: =I8-G8 -> 8 | K8: =IF(I8=0,0,J8/I8) -> 0.36363636 | L8: =E8-Overview!$C$22 -> 732 | M8: =IF(L8<0,"Expired",IF(L8<=Overview!$C$23,"Critical",IF(L8<=Overview!$C$24,"Expiring Soon",IF(L8<=Overview!$C$25,"Watch","Safe")))) -> Safe | N8: =SUMIFS(transactions!$E$2:$E$2601,transactions!$C$2:$C$2601,$A8,transactions!$D$2:$D$2601,"Purchase") -> 955 | O8: =SUMIFS(transactions!$E$2:$E$2601,transactions!$C$2:$C$2601,$A8,transactions!$D$2:$D$2601,"Sale") -> 1345 | P8: =N8-O8 -> -390 | Q8: =IF(N8=0,0,O8/N8) -> 1.408377 | R8: =SUMIFS(transactions!$N$2:$N$2601,transactions!$C$2:$C$2601,$A8) -> 29590 | S8: =SUMIFS(transactions!$P$2:$P$2601,transactions!$C$2:$C$2601,$A8) -> 10760 | T8: =IF(Q8>=Overview!$C$26,"High",IF(Q8>=Overview!$C$27,"Medium","Low")) -> Medium | U8: =RANK(O8,$O$2:$O$26) -> 21 | V8: =RANK(R8,$R$2:$R$26) -> 20 | W8: =IF(O8>=PERCENTILE($O$2:$O$26,0.75),"Fast",IF(O8<=PERCENTILE($O$2:$O$26,0.25),"Slow","Medium")) -> Slow
A9: M008 | B9: Multivitamin Tablets | C9: Vitamin | D9: B108 | E9: 46539 | F9: Wellness Pharma | G9: 72 | H9: 120 | I9: 105 | J9: =I9-G9 -> 33 | K9: =IF(I9=0,0,J9/I9) -> 0.31428571 | L9: =E9-Overview!$C$22 -> 239 | M9: =IF(L9<0,"Expired",IF(L9<=Overview!$C$23,"Critical",IF(L9<=Overview!$C$24,"Expiring Soon",IF(L9<=Overview!$C$25,"Watch","Safe")))) -> Watch | N9: =SUMIFS(transactions!$E$2:$E$2601,transactions!$C$2:$C$2601,$A9,transactions!$D$2:$D$2601,"Purchase") -> 765 | O9: =SUMIFS(transactions!$E$2:$E$2601,transactions!$C$2:$C$2601,$A9,transactions!$D$2:$D$2601,"Sale") -> 1350 | P9: =N9-O9 -> -585 | Q9: =IF(N9=0,0,O9/N9) -> 1.7647059 | R9: =SUMIFS(transactions!$N$2:$N$2601,transactions!$C$2:$C$2601,$A9) -> 141750 | S9: =SUMIFS(transactions!$P$2:$P$2601,transactions!$C$2:$C$2601,$A9) -> 44550 | T9: =IF(Q9>=Overview!$C$26,"High",IF(Q9>=Overview!$C$27,"Medium","Low")) -> High | U9: =RANK(O9,$O$2:$O$26) -> 20 | V9: =RANK(R9,$R$2:$R$26) -> 2 | W9: =IF(O9>=PERCENTILE($O$2:$O$26,0.75),"Fast",IF(O9<=PERCENTILE($O$2:$O$26,0.25),"Slow","Medium")) -> Slow
A10: M009 | B10: Omeprazole 20mg | C10: Gastric | D10: B109 | E10: 46884 | F10: XYZ Pharma | G10: 18 | H10: 30 | I10: 26 | J10: =I10-G10 -> 8 | K10: =IF(I10=0,0,J10/I10) -> 0.30769231 | L10: =E10-Overview!$C$22 -> 584 | M10: =IF(L10<0,"Expired",IF(L10<=Overview!$C$23,"Critical",IF(L10<=Overview!$C$24,"Expiring Soon",IF(L10<=Overview!$C$25,"Watch","Safe")))) -> Safe | N10: =SUMIFS(transactions!$E$2:$E$2601,transactions!$C$2:$C$2601,$A10,transactions!$D$2:$D$2601,"Purchase") -> 1425 | O10: =SUMIFS(transactions!$E$2:$E$2601,transactions!$C$2:$C$2601,$A10,transactions!$D$2:$D$2601,"Sale") -> 1400 | P10: =N10-O10 -> 25 | Q10: =IF(N10=0,0,O10/N10) -> 0.98245614 | R10: =SUMIFS(transactions!$N$2:$N$2601,transactions!$C$2:$C$2601,$A10) -> 36400 | S10: =SUMIFS(transactions!$P$2:$P$2601,transactions!$C$2:$C$2601,$A10) -> 11200 | T10: =IF(Q10>=Overview!$C$26,"High",IF(Q10>=Overview!$C$27,"Medium","Low")) -> Low | U10: =RANK(O10,$O$2:$O$26) -> 17 | V10: =RANK(R10,$R$2:$R$26) -> 16 | W10: =IF(O10>=PERCENTILE($O$2:$O$26,0.75),"Fast",IF(O10<=PERCENTILE($O$2:$O$26,0.25),"Slow","Medium")) -> Medium
A11: M010 | B11: Pantoprazole 40mg | C11: Gastric | D11: B110 | E11: 46632 | F11: HealthCare Labs | G11: 24 | H11: 40 | I11: 35 | J11: =I11-G11 -> 11 | K11: =IF(I11=0,0,J11/I11) -> 0.31428571 | L11: =E11-Overview!$C$22 -> 332 | M11: =IF(L11<0,"Expired",IF(L11<=Overview!$C$23,"Critical",IF(L11<=Overview!$C$24,"Expiring Soon",IF(L11<=Overview!$C$25,"Watch","Safe")))) -> Watch | N11: =SUMIFS(transactions!$E$2:$E$2601,transactions!$C$2:$C$2601,$A11,transactions!$D$2:$D$2601,"Purchase") -> 1000 | O11: =SUMIFS(transactions!$E$2:$E$2601,transactions!$C$2:$C$2601,$A11,transactions!$D$2:$D$2601,"Sale") -> 1545 | P11: =N11-O11 -> -545 | Q11: =IF(N11=0,0,O11/N11) -> 1.545 | R11: =SUMIFS(transactions!$N$2:$N$2601,transactions!$C$2:$C$2601,$A11) -> 54075 | S11: =SUMIFS(transactions!$P$2:$P$2601,transactions!$C$2:$C$2601,$A11) -> 16995 | T11: =IF(Q11>=Overview!$C$26,"High",IF(Q11>=Overview!$C$27,"Medium","Low")) -> Medium | U11: =RANK(O11,$O$2:$O$26) -> 7 | V11: =RANK(R11,$R$2:$R$26) -> 13 | W11: =IF(O11>=PERCENTILE($O$2:$O$26,0.75),"Fast",IF(O11<=PERCENTILE($O$2:$O$26,0.25),"Slow","Medium")) -> Fast
A12: M011 | B12: Metformin 500mg | C12: Diabetes | D12: B111 | E12: 46748 | F12: ABC Pharma | G12: 16 | H12: 28 | I12: 24 | J12: =I12-G12 -> 8 | K12: =IF(I12=0,0,J12/I12) -> 0.33333333 | L12: =E12-Overview!$C$22 -> 448 | M12: =IF(L12<0,"Expired",IF(L12<=Overview!$C$23,"Critical",IF(L12<=Overview!$C$24,"Expiring Soon",IF(L12<=Overview!$C$25,"Watch","Safe")))) -> Safe | N12: =SUMIFS(transactions!$E$2:$E$2601,transactions!$C$2:$C$2601,$A12,transactions!$D$2:$D$2601,"Purchase") -> 915 | O12: =SUMIFS(transactions!$E$2:$E$2601,transactions!$C$2:$C$2601,$A12,transactions!$D$2:$D$2601,"Sale") -> 1365 | P12: =N12-O12 -> -450 | Q12: =IF(N12=0,0,O12/N12) -> 1.4918033 | R12: =SUMIFS(transactions!$N$2:$N$2601,transactions!$C$2:$C$2601,$A12) -> 32760 | S12: =SUMIFS(transactions!$P$2:$P$2601,transactions!$C$2:$C$2601,$A12) -> 10920 | T12: =IF(Q12>=Overview!$C$26,"High",IF(Q12>=Overview!$C$27,"Medium","Low")) -> Medium | U12: =RANK(O12,$O$2:$O$26) -> 18 | V12: =RANK(R12,$R$2:$R$26) -> 17 | W12: =IF(O12>=PERCENTILE($O$2:$O$26,0.75),"Fast",IF(O12<=PERCENTILE($O$2:$O$26,0.25),"Slow","Medium")) -> Medium
A13: M012 | B13: Glimepiride 2mg | C13: Diabetes | D13: B112 | E13: 46876 | F13: Medico Ltd | G13: 38 | H13: 60 | I13: 52 | J13: =I13-G13 -> 14 | K13: =IF(I13=0,0,J13/I13) -> 0.26923077 | L13: =E13-Overview!$C$22 -> 576 | M13: =IF(L13<0,"Expired",IF(L13<=Overview!$C$23,"Critical",IF(L13<=Overview!$C$24,"Expiring Soon",IF(L13<=Overview!$C$25,"Watch","Safe")))) -> Safe | N13: =SUMIFS(transactions!$E$2:$E$2601,transactions!$C$2:$C$2601,$A13,transactions!$D$2:$D$2601,"Purchase") -> 755 | O13: =SUMIFS(transactions!$E$2:$E$2601,transactions!$C$2:$C$2601,$A13,transactions!$D$2:$D$2601,"Sale") -> 2050 | P13: =N13-O13 -> -1295 | Q13: =IF(N13=0,0,O13/N13) -> 2.7152318 | R13: =SUMIFS(transactions!$N$2:$N$2601,transactions!$C$2:$C$2601,$A13) -> 106600 | S13: =SUMIFS(transactions!$P$2:$P$2601,transactions!$C$2:$C$2601,$A13) -> 28700 | T13: =IF(Q13>=Overview!$C$26,"High",IF(Q13>=Overview!$C$27,"Medium","Low")) -> High | U13: =RANK(O13,$O$2:$O$26) -> 1 | V13: =RANK(R13,$R$2:$R$26) -> 4 | W13: =IF(O13>=PERCENTILE($O$2:$O$26,0.75),"Fast",IF(O13<=PERCENTILE($O$2:$O$26,0.25),"Slow","Medium")) -> Fast
... A26: M025 | B26: Aspirin 75mg | C26: Cardiac | D26: B125 | E26: 46877 | F26: Medico Ltd | G26: 10 | H26: 18 | I26: 15 | J26: =I26-G26 -> 5 | K26: =IF(I26=0,0,J26/I26) -> 0.33333333 | L26: =E26-Overview!$C$22 -> 577 | M26: =IF(L26<0,"Expired",IF(L26<=Overview!$C$23,"Critical",IF(L26<=Overview!$C$24,"Expiring Soon",IF(L26<=Overview!$C$25,"Watch","Safe")))) -> Safe | N26: =SUMIFS(transactions!$E$2:$E$2601,transactions!$C$2:$C$2601,$A26,transactions!$D$2:$D$2601,"Purchase") -> 1105 | O26: =SUMIFS(transactions!$E$2:$E$2601,transactions!$C$2:$C$2601,$A26,transactions!$D$2:$D$2601,"Sale") -> 1285 | P26: =N26-O26 -> -180 | Q26: =IF(N26=0,0,O26/N26) -> 1.1628959 | R26: =SUMIFS(transactions!$N$2:$N$2601,transactions!$C$2:$C$2601,$A26) -> 19275 | S26: =SUMIFS(transactions!$P$2:$P$2601,transactions!$C$2:$C$2601,$A26) -> 6425 | T26: =IF(Q26>=Overview!$C$26,"High",IF(Q26>=Overview!$C$27,"Medium","Low")) -> Low | U26: =RANK(O26,$O$2:$O$26) -> 22 | V26: =RANK(R26,$R$2:$R$26) -> 24 | W26: =IF(O26>=PERCENTILE($O$2:$O$26,0.75),"Fast",IF(O26<=PERCENTILE($O$2:$O$26,0.25),"Slow","Medium")) -> Slow
